Workbook

Sheet 日志
B1: 若判断错误，只需等待。除非可反向操作 | F1: =IFERROR(LOOKUP(2,1/(#REF!<>""),#REF!),"") | I1: =COUNTIFS(B:B,O1,M:M,"Lose") -> 0 | J1: =I1&"/3" -> 0/3 | K1: =COUNTIF(B:B,O1) -> 0 | L1: =K1&"/5" -> 0/5 | Q1: 接受亏损，然后继续 | V1: 总共胜率 | W1: 总盈亏 | X1: 平均盈利金额 | Y1: 平均亏损金额 | Z1: 盈亏比
A2: 日期 | B2: 备注 | C2: 入场理由 | D2: 类型 | E2: 离场理由/方式 | F2: 补充说明 | G2: 仓位大小 （填数字） | H2: 方向 | I2: 入场价格 | J2: 离场价格1 | K2: 离场价格2 | L2: 盈亏情况 （会自动计算） | M2: 盈亏状态 （会自动计算） | N2: 累计盈亏 （会自动计算） | P2: 错误原因 | Q2: 隐 | R2: 限 | S2: 离 | T2: 止 | U2: 记 | V2: =COUNTIF($M$3:$M$404,"win")/(COUNTIF($M$3:$M$404,"win")+COUNTIF($M$3:$M$404,"lose")) -> #DIV/0! | W2: =SUM($L$3:$L$404) -> 0 | X2: =AVERAGEIF(L:L,">0") -> #DIV/0! | Y2: =AVERAGEIF(L:L,"<0") -> #DIV/0! | Z2: =X2/-Y2 -> #DIV/0!
L3: =IF(ISBLANK(K3),IF(H3="Long",(J3-I3)*G3,(I3-J3)*G3),IF(H3="Long",(J3-I3)*(G3/2)+(K3-I3)*(G3/2),(I3-J3)*(G3/2)+(I3-K3)*(G3/2))) -> 0 | M3: =_xlfn.IFS(L3>0,"win",L3<0,"lose",L3=0,"BE") -> BE | N3: =$L$3 -> 0 | Q3: =IFERROR(LOOKUP(2,1/(B3:B1000<>""),B2:B1000),"")
L4: =IF(ISBLANK(K4),IF(H4="Long",(J4-I4)*G4,(I4-J4)*G4),IF(H4="Long",(J4-I4)*(G4/2)+(K4-I4)*(G4/2),(I4-J4)*(G4/2)+(I4-K4)*(G4/2))) -> 0 | M4: =_xlfn.IFS(L4>0,"win",L4<0,"lose",L4=0,"BE") -> BE | N4: =L4+O7 -> 0 | R4: 入场原因 （可以自己定义） | S4: 盈亏金额 | T4: 胜率 | U4: 使用次数
L5: =IF(ISBLANK(K5),IF(H5="Long",(J5-I5)*G5,(I5-J5)*G5),IF(H5="Long",(J5-I5)*(G5/2)+(K5-I5)*(G5/2),(I5-J5)*(G5/2)+(I5-K5)*(G5/2))) -> 0 | M5: =_xlfn.IFS(L5>0,"win",L5<0,"lose",L5=0,"BE") -> BE | N5: =L5+N4 -> 0 | R5: 交易区间内三推反转 | S5: =SUMIF(C:C,R5,L:L) -> 0 | T5: =IFERROR(COUNTIFS(C:C,R5,M:M,"win")/COUNTIF(C:C,R5),0) -> 0 | U5: =COUNTIF(C:C,R5) -> 0
L6: =IF(ISBLANK(K6),IF(H6="Long",(J6-I6)*G6,(I6-J6)*G6),IF(H6="Long",(J6-I6)*(G6/2)+(K6-I6)*(G6/2),(I6-J6)*(G6/2)+(I6-K6)*(G6/2))) -> 0 | M6: =_xlfn.IFS(L6>0,"win",L6<0,"lose",L6=0,"BE") -> BE | N6: =L6+N5 -> 0 | R6: 交易区间内2ndleg陷阱 | S6: =SUMIF(C:C,R6,L:L) -> 0 | T6: =IFERROR(COUNTIFS(C:C,R6,M:M,"win")/COUNTIF(C:C,R6),0) -> 0 | U6: =COUNTIF(C:C,R6) -> 0
L7: =IF(ISBLANK(K7),IF(H7="Long",(J7-I7)*G7,(I7-J7)*G7),IF(H7="Long",(J7-I7)*(G7/2)+(K7-I7)*(G7/2),(I7-J7)*(G7/2)+(I7-K7)*(G7/2))) -> 0 | M7: =_xlfn.IFS(L7>0,"win",L7<0,"lose",L7=0,"BE") -> BE | N7: =L7+N6 -> 0 | R7: 交易区间确认突破 | S7: =SUMIF(C:C,R7,L:L) -> 0 | T7: =IFERROR(COUNTIFS(C:C,R7,M:M,"win")/COUNTIF(C:C,R7),0) -> 0 | U7: =COUNTIF(C:C,R7) -> 0
L8: =IF(ISBLANK(K8),IF(H8="Long",(J8-I8)*G8,(I8-J8)*G8),IF(H8="Long",(J8-I8)*(G8/2)+(K8-I8)*(G8/2),(I8-J8)*(G8/2)+(I8-K8)*(G8/2))) -> 0 | M8: =_xlfn.IFS(L8>0,"win",L8<0,"lose",L8=0,"BE") -> BE | N8: =L8+N7 -> 0 | R8: AIL，AIS首次回调 | S8: =SUMIF(C:C,R8,L:L) -> 0 | T8: =IFERROR(COUNTIFS(C:C,R8,M:M,"win")/COUNTIF(C:C,R8),0) -> 0 | U8: =COUNTIF(C:C,R8) -> 0
L9: =IF(ISBLANK(K9),IF(H9="Long",(J9-I9)*G9,(I9-J9)*G9),IF(H9="Long",(J9-I9)*(G9/2)+(K9-I9)*(G9/2),(I9-J9)*(G9/2)+(I9-K9)*(G9/2))) -> 0 | M9: =_xlfn.IFS(L9>0,"win",L9<0,"lose",L9=0,"BE") -> BE | N9: =L9+N8 -> 0 | R9: 牛旗或熊旗 | S9: =SUMIF(C:C,R9,L:L) -> 0 | T9: =IFERROR(COUNTIFS(C:C,R9,M:M,"win")/COUNTIF(C:C,R9),0) -> 0 | U9: =COUNTIF(C:C,R9) -> 0
L10: =IF(ISBLANK(K10),IF(H10="Long",(J10-I10)*G10,(I10-J10)*G10),IF(H10="Long",(J10-I10)*(G10/2)+(K10-I10)*(G10/2),(I10-J10)*(G10/2)+(I10-K10)*(G10/2))) -> 0 | M10: =_xlfn.IFS(L10>0,"win",L10<0,"lose",L10=0,"BE") -> BE | N10: =L10+N9 -> 0 | R10: 三推楔形、信号k | S10: =SUMIF(C:C,R10,L:L) -> 0 | T10: =IFERROR(COUNTIFS(C:C,R10,M:M,"win")/COUNTIF(C:C,R10),0) -> 0 | U10: =COUNTIF(C:C,R10) -> 0
L11: =IF(ISBLANK(K11),IF(H11="Long",(J11-I11)*G11,(I11-J11)*G11),IF(H11="Long",(J11-I11)*(G11/2)+(K11-I11)*(G11/2),(I11-J11)*(G11/2)+(I11-K11)*(G11/2))) -> 0 | M11: =_xlfn.IFS(L11>0,"win",L11<0,"lose",L11=0,"BE") -> BE | N11: =L11+N10 -> 0 | R11: 三推楔形、双底 | S11: =SUMIF(C:C,R11,L:L) -> 0 | T11: =IFERROR(COUNTIFS(C:C,R11,M:M,"win")/COUNTIF(C:C,R11),0) -> 0 | U11: =COUNTIF(C:C,R11) -> 0
L12: =IF(ISBLANK(K12),IF(H12="Long",(J12-I12)*G12,(I12-J12)*G12),IF(H12="Long",(J12-I12)*(G12/2)+(K12-I12)*(G12/2),(I12-J12)*(G12/2)+(I12-K12)*(G12/2))) -> 0 | M12: =_xlfn.IFS(L12>0,"win",L12<0,"lose",L12=0,"BE") -> BE | N12: =L12+N11 -> 0 | R12: 嵌套三推楔形 | S12: =SUMIF(C:C,R12,L:L) -> 0 | T12: =IFERROR(COUNTIFS(C:C,R12,M:M,"win")/COUNTIF(C:C,R12),0) -> 0 | U12: =COUNTIF(C:C,R12) -> 0
L13: =IF(ISBLANK(K13),IF(H13="Long",(J13-I13)*G13,(I13-J13)*G13),IF(H13="Long",(J13-I13)*(G13/2)+(K13-I13)*(G13/2),(I13-J13)*(G13/2)+(I13-K13)*(G13/2))) -> 0 | M13: =_xlfn.IFS(L13>0,"win",L13<0,"lose",L13=0,"BE") -> BE | N13: =L13+N12 -> 0 | R13: 嵌套楔形、高潮、信号K | S13: =SUMIF(C:C,R13,L:L) -> 0 | T13: =IFERROR(COUNTIFS(C:C,R13,M:M,"win")/COUNTIF(C:C,R13),0) -> 0 | U13: =COUNTIF(C:C,R13) -> 0
L14: =IF(ISBLANK(K14),IF(H14="Long",(J14-I14)*G14,(I14-J14)*G14),IF(H14="Long",(J14-I14)*(G14/2)+(K14-I14)*(G14/2),(I14-J14)*(G14/2)+(I14-K14)*(G14/2))) -> 0 | M14: =_xlfn.IFS(L14>0,"win",L14<0,"lose",L14=0,"BE") -> BE | N14: =L14+N13 -> 0 | R14: 三重底 | S14: =SUMIF(C:C,R14,L:L) -> 0 | T14: =IFERROR(COUNTIFS(C:C,R14,M:M,"win")/COUNTIF(C:C,R14),0) -> 0 | U14: =COUNTIF(C:C,R14) -> 0
L15: =IF(ISBLANK(K15),IF(H15="Long",(J15-I15)*G15,(I15-J15)*G15),IF(H15="Long",(J15-I15)*(G15/2)+(K15-I15)*(G15/2),(I15-J15)*(G15/2)+(I15-K15)*(G15/2))) -> 0 | M15: =_xlfn.IFS(L15>0,"win",L15<0,"lose",L15=0,"BE") -> BE | N15: =L15+N14 -> 0 | R15: 三推楔形、双顶 | S15: =SUMIF(C:C,R15,L:L) -> 0 | T15: =IFERROR(COUNTIFS(C:C,R15,M:M,"win")/COUNTIF(C:C,R15),0) -> 0 | U15: =COUNTIF(C:C,R15) -> 0
L16: =IF(ISBLANK(K16),IF(H16="Long",(J16-I16)*G16,(I16-J16)*G16),IF(H16="Long",(J16-I16)*(G16/2)+(K16-I16)*(G16/2),(I16-J16)*(G16/2)+(I16-K16)*(G16/2))) -> 0 | M16: =_xlfn.IFS(L16>0,"win",L16<0,"lose",L16=0,"BE") -> BE | N16: =L16+N15 -> 0 | R16: 交易区间上下沿、信号K | S16: =SUMIF(C:C,R16,L:L) -> 0 | T16: =IFERROR(COUNTIFS(C:C,R16,M:M,"win")/COUNTIF(C:C,R16),0) -> 0 | U16: =COUNTIF(C:C,R16) -> 0
... L23: =IF(ISBLANK(K23),IF(H23="Long",(J23-I23)*G23,(I23-J23)*G23),IF(H23="Long",(J23-I23)*(G23/2)+(K23-I23)*(G23/2),(I23-J23)*(G23/2)+(I23-K23)*(G23/2))) -> 0 | M23: =_xlfn.IFS(L23>0,"win",L23<0,"lose",L23=0,"BE") -> BE | N23: =L23+N22 -> 0 | R23: 抛物线楔形、信号K | S23: =SUMIF(C:C,R23,L:L) -> 0 | T23: =IFERROR(COUNTIFS(C:C,R23,M:M,"win")/COUNTIF(C:C,R23),0) -> 0 | U23: =COUNTIF(C:C,R23) -> 0
L24: =IF(ISBLANK(K24),IF(H24="Long",(J24-I24)*G24,(I24-J24)*G24),IF(H24="Long",(J24-I24)*(G24/2)+(K24-I24)*(G24/2),(I24-J24)*(G24/2)+(I24-K24)*(G24/2))) -> 0 | M24: =_xlfn.IFS(L24>0,"win",L24<0,"lose",L24=0,"BE") -> BE | N24: =L24+N23 -> 0 | R24: 趋势线、信号K | S24: =SUMIF(C:C,R24,L:L) -> 0 | T24: =IFERROR(COUNTIFS(C:C,R24,M:M,"win")/COUNTIF(C:C,R24),0) -> 0 | U24: =COUNTIF(C:C,R24) -> 0 | X24: 做多 | Y24: 横盘 | Z24: 做空
L25: =IF(ISBLANK(K25),IF(H25="Long",(J25-I25)*G25,(I25-J25)*G25),IF(H25="Long",(J25-I25)*(G25/2)+(K25-I25)*(G25/2),(I25-J25)*(G25/2)+(I25-K25)*(G25/2))) -> 0 | M25: =_xlfn.IFS(L25>0,"win",L25<0,"lose",L25=0,"BE") -> BE | N25: =L25+N24 -> 0 | R25: H1、L1 | S25: =SUMIF(C:C,R25,L:L) -> 0 | T25: =IFERROR(COUNTIFS(C:C,R25,M:M,"win")/COUNTIF(C:C,R25),0) -> 0 | U25: =COUNTIF(C:C,R25) -> 0 | W25: 上涨 | X25: 回调后的第二次进场信号 , 首次突破通道, 突破前高后产生了更高的高点, 第二次回踩缺口k线, 突破测试 | Y25: 交易区间 | Z25: W结构, W 结构突破后的首次回调
L26: =IF(ISBLANK(K26),IF(H26="Long",(J26-I26)*G26,(I26-J26)*G26),IF(H26="Long",(J26-I26)*(G26/2)+(K26-I26)*(G26/2),(I26-J26)*(G26/2)+(I26-K26)*(G26/2))) -> 0 | M26: =_xlfn.IFS(L26>0,"win",L26<0,"lose",L26=0,"BE") -> BE | N26: =L26+N25 -> 0 | R26: H2、L2 | S26: =SUMIF(C:C,R26,L:L) -> 0 | T26: =IFERROR(COUNTIFS(C:C,R26,M:M,"win")/COUNTIF(C:C,R26),0) -> 0 | U26: =COUNTIF(C:C,R26) -> 0 | W26: 横盘 | X26: 突破 | Y26: 假突破 | Z26: 突破
L27: =IF(ISBLANK(K27),IF(H27="Long",(J27-I27)*G27,(I27-J27)*G27),IF(H27="Long",(J27-I27)*(G27/2)+(K27-I27)*(G27/2),(I27-J27)*(G27/2)+(I27-K27)*(G27/2))) -> 0 | M27: =_xlfn.IFS(L27>0,"win",L27<0,"lose",L27=0,"BE") -> BE | N27: =L27+N26 -> 0 | R27: 不知道为什么开仓 | S27: =SUMIF(C:C,R27,L:L) -> 0 | T27: =IFERROR(COUNTIFS(C:C,R27,M:M,"win")/COUNTIF(C:C,R27),0) -> 0 | U27: =COUNTIF(C:C,R27) -> 0 | W27: 下跌 | X27: W结构, W 结构突破后的首次回调 | Y27: 交易区间 | Z27: 回调后的第二次进场信号 , 首次突破通道, 突破前高后产生了更高的高点, 第二次回踩缺口k线, 突破测试
L28: =IF(ISBLANK(K28),IF(H28="Long",(J28-I28)*G28,(I28-J28)*G28),IF(H28="Long",(J28-I28)*(G28/2)+(K28-I28)*(G28/2),(I28-J28)*(G28/2)+(I28-K28)*(G28/2))) -> 0 | M28: =_xlfn.IFS(L28>0,"win",L28<0,"lose",L28=0,"BE") -> BE | N28: =L28+N27 -> 0
L29: =IF(ISBLANK(K29),IF(H29="Long",(J29-I29)*G29,(I29-J29)*G29),IF(H29="Long",(J29-I29)*(G29/2)+(K29-I29)*(G29/2),(I29-J29)*(G29/2)+(I29-K29)*(G29/2))) -> 0 | M29: =_xlfn.IFS(L29>0,"win",L29<0,"lose",L29=0,"BE") -> BE | N29: =L29+N28 -> 0 | W29: 突破 | X29: 收敛三角旗形 | Y29: 当前趋势强势延续 | Z29: 回调
L30: =IF(ISBLANK(K30),IF(H30="Long",(J30-I30)*G30,(I30-J30)*G30),IF(H30="Long",(J30-I30)*(G30/2)+(K30-I30)*(G30/2),(I30-J30)*(G30/2)+(I30-K30)*(G30/2))) -> 0 | M30: =_xlfn.IFS(L30>0,"win",L30<0,"lose",L30=0,"BE") -> BE | N30: =L30+N29 -> 0 | W30: 假突破 | X30: 突破后反转 | Y30: 反转k | Z30: 深度回调
L31: =IF(ISBLANK(K31),IF(H31="Long",(J31-I31)*G31,(I31-J31)*G31),IF(H31="Long",(J31-I31)*(G31/2)+(K31-I31)*(G31/2),(I31-J31)*(G31/2)+(I31-K31)*(G31/2))) -> 0 | M31: =_xlfn.IFS(L31>0,"win",L31<0,"lose",L31=0,"BE") -> BE | N31: =L31+N30 -> 0 | W31: 趋势转换 | X31: 双底/双顶 | Y31: 窄交易区间 | Z31: 反转失败+第二次入场信号失效
L32: =IF(ISBLANK(K32),IF(H32="Long",(J32-I32)*G32,(I32-J32)*G32),IF(H32="Long",(J32-I32)*(G32/2)+(K32-I32)*(G32/2),(I32-J32)*(G32/2)+(I32-K32)*(G32/2))) -> 0 | M32: =_xlfn.IFS(L32>0,"win",L32<0,"lose",L32=0,"BE") -> BE | N32: =L32+N31 -> 0 | X32: 首次回调 | Z32: 首次反转
L33: =IF(ISBLANK(K33),IF(H33="Long",(J33-I33)*G33,(I33-J33)*G33),IF(H33="Long",(J33-I33)*(G33/2)+(K33-I33)*(G33/2),(I33-J33)*(G33/2)+(I33-K33)*(G33/2))) -> 0 | M33: =_xlfn.IFS(L33>0,"win",L33<0,"lose",L33=0,"BE") -> BE | N33: =L33+N32 -> 0 | Z33: 假突破
L34: =IF(ISBLANK(K34),IF(H34="Long",(J34-I34)*G34,(I34-J34)*G34),IF(H34="Long",(J34-I34)*(G34/2)+(K34-I34)*(G34/2),(I34-J34)*(G34/2)+(I34-K34)*(G34/2))) -> 0 | M34: =_xlfn.IFS(L34>0,"win",L34<0,"lose",L34=0,"BE") -> BE | N34: =L34+N33 -> 0 | R34: 类型 | S34: 盈利金额 | T34: 胜率 | U34: 使用次数 | X34: 突破失败 | Z34: 开盘区间
L35: =IF(ISBLANK(K35),IF(H35="Long",(J35-I35)*G35,(I35-J35)*G35),IF(H35="Long",(J35-I35)*(G35/2)+(K35-I35)*(G35/2),(I35-J35)*(G35/2)+(I35-K35)*(G35/2))) -> 0 | M35: =_xlfn.IFS(L35>0,"win",L35<0,"lose",L35=0,"BE") -> BE | N35: =L35+N34 -> 0 | R35: 趋势延续（Continuation） | S35: =SUMIF(D:D,R35,L:L) -> 0 | T35: =IFERROR(COUNTIFS(D:D,R35,M:M,"win")/COUNTIF(D:D,R35),0) -> 0 | U35: =COUNTIF(D:D,R35) -> 0 | Z35: 多周期共振
L36: =IF(ISBLANK(K36),IF(H36="Long",(J36-I36)*G36,(I36-J36)*G36),IF(H36="Long",(J36-I36)*(G36/2)+(K36-I36)*(G36/2),(I36-J36)*(G36/2)+(I36-K36)*(G36/2))) -> 0 | M36: =_xlfn.IFS(L36>0,"win",L36<0,"lose",L36=0,"BE") -> BE | N36: =L36+N35 -> 0 | R36: 反转（Reversal） | S36: =SUMIF(D:D,R36,L:L) -> 0 | T36: =IFERROR(COUNTIFS(D:D,R36,M:M,"win")/COUNTIF(D:D,R36),0) -> 0 | U36: =COUNTIF(D:D,R36) -> 0
L37: =IF(ISBLANK(K37),IF(H37="Long",(J37-I37)*G37,(I37-J37)*G37),IF(H37="Long",(J37-I37)*(G37/2)+(K37-I37)*(G37/2),(I37-J37)*(G37/2)+(I37-K37)*(G37/2))) -> 0 | M37: =_xlfn.IFS(L37>0,"win",L37<0,"lose",L37=0,"BE") -> BE | N37: =L37+N36 -> 0 | R37: 突破（BO） | S37: =SUMIF(D:D,R37,L:L) -> 0 | T37: =IFERROR(COUNTIFS(D:D,R37,M:M,"win")/COUNTIF(D:D,R37),0) -> 0 | U37: =COUNTIF(D:D,R37) -> 0
L38: =IF(ISBLANK(K38),IF(H38="Long",(J38-I38)*G38,(I38-J38)*G38),IF(H38="Long",(J38-I38)*(G38/2)+(K38-I38)*(G38/2),(I38-J38)*(G38/2)+(I38-K38)*(G38/2))) -> 0 | M38: =_xlfn.IFS(L38>0,"win",L38<0,"lose",L38=0,"BE") -> BE | N38: =L38+N37 -> 0 | P38: 错误的信号k线（Wrong Signal bar） | R38: 假突破（fBO） | S38: =SUMIF(D:D,R38,L:L) -> 0 | T38: =IFERROR(COUNTIFS(D:D,R38,M:M,"win")/COUNTIF(D:D,R38),0) -> 0 | U38: =COUNTIF(D:D,R38) -> 0
L39: =IF(ISBLANK(K39),IF(H39="Long",(J39-I39)*G39,(I39-J39)*G39),IF(H39="Long",(J39-I39)*(G39/2)+(K39-I39)*(G39/2),(I39-J39)*(G39/2)+(I39-K39)*(G39/2))) -> 0 | M39: =_xlfn.IFS(L39>0,"win",L39<0,"lose",L39=0,"BE") -> BE | N39: =L39+N38 -> 0
L40: =IF(ISBLANK(K40),IF(H40="Long",(J40-I40)*G40,(I40-J40)*G40),IF(H40="Long",(J40-I40)*(G40/2)+(K40-I40)*(G40/2),(I40-J40)*(G40/2)+(I40-K40)*(G40/2))) -> 0 | M40: =_xlfn.IFS(L40>0,"win",L40<0,"lose",L40=0,"BE") -> BE | N40: =L40+N39 -> 0
L41: =IF(ISBLANK(K41),IF(H41="Long",(J41-I41)*G41,(I41-J41)*G41),IF(H41="Long",(J41-I41)*(G41/2)+(K41-I41)*(G41/2),(I41-J41)*(G41/2)+(I41-K41)*(G41/2))) -> 0 | M41: =_xlfn.IFS(L41>0,"win",L41<0,"lose",L41=0,"BE") -> BE | N41: =L41+N40 -> 0
L42: =IF(ISBLANK(K42),IF(H42="Long",(J42-I42)*G42,(I42-J42)*G42),IF(H42="Long",(J42-I42)*(G42/2)+(K42-I42)*(G42/2),(I42-J42)*(G42/2)+(I42-K42)*(G42/2))) -> 0 | M42: =_xlfn.IFS(L42>0,"win",L42<0,"lose",L42=0,"BE") -> BE | N42: =L42+N41 -> 0
L43: =IF(ISBLANK(K43),IF(H43="Long",(J43-I43)*G43,(I43-J43)*G43),IF(H43="Long",(J43-I43)*(G43/2)+(K43-I43)*(G43/2),(I43-J43)*(G43/2)+(I43-K43)*(G43/2))) -> 0 | M43: =_xlfn.IFS(L43>0,"win",L43<0,"lose",L43=0,"BE") -> BE | N43: =L43+N42 -> 0
L44: =IF(ISBLANK(K44),IF(H44="Long",(J44-I44)*G44,(I44-J44)*G44),IF(H44="Long",(J44-I44)*(G44/2)+(K44-I44)*(G44/2),(I44-J44)*(G44/2)+(I44-K44)*(G44/2))) -> 0 | M44: =_xlfn.IFS(L44>0,"win",L44<0,"lose",L44=0,"BE") -> BE | N44: =L44+N43 -> 0 | P44: 错误的信号k线（Wrong Signal bar）
L45: =IF(ISBLANK(K45),IF(H45="Long",(J45-I45)*G45,(I45-J45)*G45),IF(H45="Long",(J45-I45)*(G45/2)+(K45-I45)*(G45/2),(I45-J45)*(G45/2)+(I45-K45)*(G45/2))) -> 0 | M45: =_xlfn.IFS(L45>0,"win",L45<0,"lose",L45=0,"BE") -> BE | N45: =L45+N44 -> 0 | P45: 错误的信号k线（Wrong Signal bar）
L46: =IF(ISBLANK(K46),IF(H46="Long",(J46-I46)*G46,(I46-J46)*G46),IF(H46="Long",(J46-I46)*(G46/2)+(K46-I46)*(G46/2),(I46-J46)*(G46/2)+(I46-K46)*(G46/2))) -> 0 | M46: =_xlfn.IFS(L46>0,"win",L46<0,"lose",L46=0,"BE") -> BE | N46: =L46+N45 -> 0 | P46: 突破/反转判断错误（BW/OL）
...

Sheet 错误类型
A1: 错误原因 | B1: 计数 | D1: 离场理由
A2: 逆势交易（Fading a strong trend） | B2: =COUNTIF(日志!$P3:$P1048576,错误类型!A2) -> 0 | D2: 回测三推起点
A3: 盈利单但是提前离场(Letting a winning trade turn to losing) | B3: =COUNTIF(日志!$P3:$P1048576,错误类型!A3) -> 0 | D3: 止盈太远
A4: 突破/反转判断错误（BW/OL） | B4: =COUNTIF(日志!$P3:$P1048576,错误类型!A4) -> 1 | D4: 推保本
A5: 错误的信号k线（Wrong Signal bar） | B5: =COUNTIF(日志!$P3:$P1048576,错误类型!A5) -> 3 | D5: EMA20
A6: 限价单入场（limit entry） | B6: =COUNTIF(日志!$P3:$P1048576,错误类型!A6) -> 0 | D6: 移动止盈
A7: k线未收线就入场（Entry mid-bar） | B7: =COUNTIF(日志!$P3:$P1048576,错误类型!A7) -> 0 | D7: 止损触发（Stop out）
A8: 在阻力位买入，在支撑位卖出（buy into resist, sell into support） | B8: =COUNTIF(日志!$P3:$P1048576,错误类型!A8) -> 0 | D8: 觉得有逆势压提前止盈
A9: 浮亏加仓（scaling into a losing position）. | B9: =COUNTIF(日志!$P3:$P1048576,错误类型!A9) -> 0 | D9: 1倍MM
A10: 市场背景理解错误（bad structure reading） | B10: =COUNTIF(日志!$P3:$P1048576,错误类型!A10) -> 0 | D10: 2倍MM
D11: 趋势线

Sheet 别瞎搞日记本
A1: 日期 | B1: 是否执行规则？ | C1: 是否情绪稳定？ | D1: 是否做记录？ | E1: 是否提前准备？ | F1: 没有 FOMO？ | G1: 总盈亏 | H1: 备注
A2: 45762 | B2: ✅ | C2: ✅ | D2: ✅ | E2: ✅ | F2: ✅ | G2: -14
A3: 45763 | B3: ❌ | C3: ❌ | D3: ❌ | E3: ✅ | F3: ❌ | G3: -60
